<robot name="rupert">

  <!-- Base (robustecendo a base e fixando o movimento) -->
  <link name="base_box">
    <visual>
      <origin xyz="0 0 0.6" rpy="0 0 0"/>
      <geometry>
        <box size="0.5 0.5 0.2"/>
      </geometry>
      <material name="white">
        <color rgba="1 1 1 1"/>
      </material>
    </visual>

    <collision>
      <origin xyz="0 0 0.6" rpy="0 0 0"/>
      <geometry>
        <box size="0.5 0.5 0.2"/>
      </geometry>
    </collision>

    <inertial>
      <origin xyz="0 0 0" rpy="0 0 0"/>
      <mass value="1"/>
      <inertia ixx="0.000034533333" ixy="0" ixz="0" iyx="0" iyy="0.000034533333" iyz="0" izx="0" izy="0" izz="0.0000648"/>
    </inertial>
  </link>

  <!-- Joint 1: Rotação no eixo Y -->
  <link name="link1">
    <visual>
      <origin xyz="0 0 0.25" rpy="0 0 0"/>
      <geometry>
        <box size="0.05 0.05 0.5"/>
      </geometry>
      <material name="red">
        <color rgba="1 0 0 1"/>
      </material>
    </visual>

    <collision>
      <origin xyz="0 0 0.25" rpy="0 0 0"/>
      <geometry>
        <box size="0.05 0.05 0.5"/>
      </geometry>
    </collision>

    <inertial>
      <origin xyz="0 0 0" rpy="0 0 0"/>
      <mass value="0.1"/>
      <inertia ixx="0.000034533333" ixy="0" ixz="0" iyx="0" iyy="0.000034533333" iyz="0" izx="0" izy="0" izz="0.0000648"/>
    </inertial>
  </link>

  <!-- Joint 1: Revolute, Movimento de rotação no eixo Y -->
  <joint name="joint1" type="revolute">
    <parent link="base_box"/>
    <child link="link1"/>
    <origin xyz="0 0.4 0.6" rpy="0 0 0"/>
    <axis xyz="0 1 0"/>
    <limit effort="10" velocity="2" lower="0" upper="3.14"/>
  </joint>

  <!-- Link 2: Movimento de subida e descida (Plano X-Y) -->
  <link name="link2">
    <visual>
      <origin xyz="0 0 0.25" rpy="0 0 0"/>
      <geometry>
        <box size="0.05 0.05 0.5"/>
      </geometry>
      <material name="green">
        <color rgba="0 1 0 1"/>
      </material>
    </visual>

    <collision>
      <origin xyz="0 0 0.25" rpy="0 0 0"/>
      <geometry>
        <box size="0.05 0.05 0.5"/>
      </geometry>
    </collision>

    <inertial>
      <origin xyz="0 0 0" rpy="0 0 0"/>
      <mass value="0.1"/>
      <inertia ixx="0.000034533333" ixy="0" ixz="0" iyx="0" iyy="0.000034533333" iyz="0" izx="0" izy="0" izz="0.0000648"/>
    </inertial>
  </link>

  <!-- Joint 2: Prismatic, Movimento no plano X-Y -->
  <joint name="joint2" type="prismatic">
    <parent link="link1"/>
    <child link="link2"/>
    <origin xyz="0 0 0.5" rpy="0 0 0"/>
    <axis xyz="1 0 0"/>
    <limit effort="10" lower="0" upper="1"/>
  </joint>

  <!-- Camara e Sensor -->
  <link name="camera_link">
    <visual>
      <origin xyz="0.0 0.0 0.0" rpy="0 0 0"/>
      <geometry>
        <box size="0.01 0.01 0.01"/>
      </geometry>
      <material name="black">
        <color rgba="0 0 0 1"/>
      </material>
    </visual>

    <collision>
      <origin xyz="0.0 0.0 0.0" rpy="0 0 0"/>
      <geometry>
        <box size="0.01 0.01 0.01"/>
      </geometry>
    </collision>

    <inertial>
      <origin xyz="0 0 0" rpy="0 0 0"/>
      <mass value="0.0001"/>
      <inertia ixx="0.000034533333" ixy="0" ixz="0" iyx="0" iyy="0.000034533333" iyz="0" izx="0" izy="0" izz="0.0000648"/>
    </inertial>
  </link>

  <joint name="camera_joint" type="fixed">
    <parent link="link2"/>
    <child link="camera_link"/>
    <origin xyz="0.03 0.0 0.495" rpy="0 0 0"/>
    <axis xyz="0 0 1"/>
  </joint>

</robot>
